Workbook

Sheet Outstanding_checkout
A1: ID | B1: Date | C1: Name | D1: Email | E1: Equipment Description | F1: Duplicate | G1: Equipment ID | H1: Expected Return Date | I1: Checked out by | J1: Checked in by | K1: Returned Date | L1: Notes
A2: 911546290 | B2: 44805 | C2: =IF(ISBLANK(A2),"Name",IF(ISNA(VLOOKUP(A2,'Master List'!A:C,2,FALSE)), "Not Found", VLOOKUP(A2,'Master List'!A:C,2,FALSE))) -> Amilcar Castillo Ortiz | D2: =IF(ISBLANK(A2), "Email",IF(ISNA(VLOOKUP(A2,'Master List'!A:C,3,FALSE)), "Not Found", VLOOKUP(A2,'Master List'!A:C,3,FALSE))) -> amilco@sfsu.edu | E2: VGA > HDMI Adapter | F2: =IF(OR(A2="",E2="","",A2="?",E2="?"),"duplicate?",IF(COUNTIFS($A:A,A2,E:E,E2)>1,"yes","no")) -> no | G2: NA | H2: 45282 | K2: =IF(J2="","Date",IF(J2<>"",IF(K2="Date",NOW(),K2),"")) -> Date
A3: 922886247 | B3: 44805 | C3: =IF(ISBLANK(A3),"Name",IF(ISNA(VLOOKUP(A3,'Master List'!A:C,2,FALSE)), "Not Found", VLOOKUP(A3,'Master List'!A:C,2,FALSE))) -> Belinda Reyes | D3: =IF(ISBLANK(A3), "Email",IF(ISNA(VLOOKUP(A3,'Master List'!A:C,3,FALSE)), "Not Found", VLOOKUP(A3,'Master List'!A:C,3,FALSE))) -> belinda.reyes124@gmail.com | E3: ? | F3: =IF(OR(A3="",E3="","",A3="?",E3="?"),"duplicate?",IF(COUNTIFS($A:A,A3,E:E,E3)>1,"yes","no")) -> duplicate? | G3: N/A | H3: 45282 | K3: =IF(J3="","Date",IF(J3<>"",IF(K3="Date",NOW(),K3),"")) -> Date
A4: 909749144 | B4: 44805 | C4: =IF(ISBLANK(A4),"Name",IF(ISNA(VLOOKUP(A4,'Master List'!A:C,2,FALSE)), "Not Found", VLOOKUP(A4,'Master List'!A:C,2,FALSE))) -> Erica Maciel | D4: =IF(ISBLANK(A4), "Email",IF(ISNA(VLOOKUP(A4,'Master List'!A:C,3,FALSE)), "Not Found", VLOOKUP(A4,'Master List'!A:C,3,FALSE))) -> emaciel@sfsu.edu | E4: VGA > USB-C Adapter Adapter | F4: =IF(OR(A4="",E4="","",A4="?",E4="?"),"duplicate?",IF(COUNTIFS($A:A,A4,E:E,E4)>1,"yes","no")) -> no | G4: N/A | H4: 45282 | K4: =IF(J4="","Date",IF(J4<>"",IF(K4="Date",NOW(),K4),"")) -> Date
A5: 909749144 | B5: 44805 | C5: =IF(ISBLANK(A5),"Name",IF(ISNA(VLOOKUP(A5,'Master List'!A:C,2,FALSE)), "Not Found", VLOOKUP(A5,'Master List'!A:C,2,FALSE))) -> Erica Maciel | D5: =IF(ISBLANK(A5), "Email",IF(ISNA(VLOOKUP(A5,'Master List'!A:C,3,FALSE)), "Not Found", VLOOKUP(A5,'Master List'!A:C,3,FALSE))) -> emaciel@sfsu.edu | E5: VGA > HDMI Adapter Adapter | F5: =IF(OR(A5="",E5="","",A5="?",E5="?"),"duplicate?",IF(COUNTIFS($A:A,A5,E:E,E5)>1,"yes","no")) -> no | G5: NA | H5: 45282 | K5: =IF(J5="","Date",IF(J5<>"",IF(K5="Date",NOW(),K5),"")) -> Date
A6: 918830723 | B6: 44805 | C6: =IF(ISBLANK(A6),"Name",IF(ISNA(VLOOKUP(A6,'Master List'!A:C,2,FALSE)), "Not Found", VLOOKUP(A6,'Master List'!A:C,2,FALSE))) -> Jesus Solorio | D6: =IF(ISBLANK(A6), "Email",IF(ISNA(VLOOKUP(A6,'Master List'!A:C,3,FALSE)), "Not Found", VLOOKUP(A6,'Master List'!A:C,3,FALSE))) -> jesussolorio@sfsu.edu | E6: VGA > USB-C Adapter Adapter | F6: =IF(OR(A6="",E6="","",A6="?",E6="?"),"duplicate?",IF(COUNTIFS($A:A,A6,E:E,E6)>1,"yes","no")) -> no | G6: NA | H6: 45282 | K6: =IF(J6="","Date",IF(J6<>"",IF(K6="Date",NOW(),K6),"")) -> Date
A7: 901118496 | B7: 44805 | C7: =IF(ISBLANK(A7),"Name",IF(ISNA(VLOOKUP(A7,'Master List'!A:C,2,FALSE)), "Not Found", VLOOKUP(A7,'Master List'!A:C,2,FALSE))) -> Marilyn Smulyan | D7: =IF(ISBLANK(A7), "Email",IF(ISNA(VLOOKUP(A7,'Master List'!A:C,3,FALSE)), "Not Found", VLOOKUP(A7,'Master List'!A:C,3,FALSE))) -> msmulyan@sfsu.edu | E7: VGA > USB-C Adapter Adapter | F7: =IF(OR(A7="",E7="","",A7="?",E7="?"),"duplicate?",IF(COUNTIFS($A:A,A7,E:E,E7)>1,"yes","no")) -> no | G7: NA | H7: 45283 | K7: =IF(J7="","Date",IF(J7<>"",IF(K7="Date",NOW(),K7),"")) -> Date
A8: 915081692 | B8: 44805 | C8: =IF(ISBLANK(A8),"Name",IF(ISNA(VLOOKUP(A8,'Master List'!A:C,2,FALSE)), "Not Found", VLOOKUP(A8,'Master List'!A:C,2,FALSE))) -> Nereyda Valdez | D8: =IF(ISBLANK(A8), "Email",IF(ISNA(VLOOKUP(A8,'Master List'!A:C,3,FALSE)), "Not Found", VLOOKUP(A8,'Master List'!A:C,3,FALSE))) -> nmonteci@sfsu.edu | E8: HDMI > MDP Adapter Adapter | F8: =IF(OR(A8="",E8="","",A8="?",E8="?"),"duplicate?",IF(COUNTIFS($A:A,A8,E:E,E8)>1,"yes","no")) -> no | G8: NA | H8: 45282 | K8: =IF(J8="","Date",IF(J8<>"",IF(K8="Date",NOW(),K8),"")) -> Date
A9: 901130898 | B9: 44805 | C9: =IF(ISBLANK(A9),"Name",IF(ISNA(VLOOKUP(A9,'Master List'!A:C,2,FALSE)), "Not Found", VLOOKUP(A9,'Master List'!A:C,2,FALSE))) -> Patricia Van Velsor | D9: =IF(ISBLANK(A9), "Email",IF(ISNA(VLOOKUP(A9,'Master List'!A:C,3,FALSE)), "Not Found", VLOOKUP(A9,'Master List'!A:C,3,FALSE))) -> pvanvels@sfsu.edu | E9: VGA > USB-C Adapter Adapter | F9: =IF(OR(A9="",E9="","",A9="?",E9="?"),"duplicate?",IF(COUNTIFS($A:A,A9,E:E,E9)>1,"yes","no")) -> no | G9: NA | H9: 45282 | K9: =IF(J9="","Date",IF(J9<>"",IF(K9="Date",NOW(),K9),"")) -> Date
A10: 918103178 | B10: 44805 | C10: =IF(ISBLANK(A10),"Name",IF(ISNA(VLOOKUP(A10,'Master List'!A:C,2,FALSE)), "Not Found", VLOOKUP(A10,'Master List'!A:C,2,FALSE))) -> Veronica Rabelo | D10: =IF(ISBLANK(A10), "Email",IF(ISNA(VLOOKUP(A10,'Master List'!A:C,3,FALSE)), "Not Found", VLOOKUP(A10,'Master List'!A:C,3,FALSE))) -> rabelo@sfsu.edu | E10: HDMI > USB-C Adapter | F10: =IF(OR(A10="",E10="","",A10="?",E10="?"),"duplicate?",IF(COUNTIFS($A:A,A10,E:E,E10)>1,"yes","no")) -> no | G10: NA | H10: 45282 | K10: =IF(J10="","Date",IF(J10<>"",IF(K10="Date",NOW(),K10),"")) -> Date
A11: 900018215 | B11: 44805 | C11: =IF(ISBLANK(A11),"Name",IF(ISNA(VLOOKUP(A11,'Master List'!A:C,2,FALSE)), "Not Found", VLOOKUP(A11,'Master List'!A:C,2,FALSE))) -> Vivian Chavez | D11: =IF(ISBLANK(A11), "Email",IF(ISNA(VLOOKUP(A11,'Master List'!A:C,3,FALSE)), "Not Found", VLOOKUP(A11,'Master List'!A:C,3,FALSE))) -> vchavez@sfsu.edu | E11: Mac Power Adapter (USB-C) | F11: =IF(OR(A11="",E11="","",A11="?",E11="?"),"duplicate?",IF(COUNTIFS($A:A,A11,E:E,E11)>1,"yes","no")) -> no | G11: N/A | H11: Indefinite | K11: =IF(J11="","Date",IF(J11<>"",IF(K11="Date",NOW(),K11),"")) -> Date
A12: 917117336 | B12: 44806 | C12: =IF(ISBLANK(A12),"Name",IF(ISNA(VLOOKUP(A12,'Master List'!A:C,2,FALSE)), "Not Found", VLOOKUP(A12,'Master List'!A:C,2,FALSE))) -> Bruna Mota | D12: =IF(ISBLANK(A12), "Email",IF(ISNA(VLOOKUP(A12,'Master List'!A:C,3,FALSE)), "Not Found", VLOOKUP(A12,'Master List'!A:C,3,FALSE))) -> bmota@mail.sfsu.edu | E12: VGA > USB-C Adapter Adapter | F12: =IF(OR(A12="",E12="","",A12="?",E12="?"),"duplicate?",IF(COUNTIFS($A:A,A12,E:E,E12)>1,"yes","no")) -> no | G12: NA | H12: 45282 | K12: =IF(J12="","Date",IF(J12<>"",IF(K12="Date",NOW(),K12),"")) -> Date
A13: 916467726 | B13: 44806 | C13: =IF(ISBLANK(A13),"Name",IF(ISNA(VLOOKUP(A13,'Master List'!A:C,2,FALSE)), "Not Found", VLOOKUP(A13,'Master List'!A:C,2,FALSE))) -> Edwin Ochong | D13: =IF(ISBLANK(A13), "Email",IF(ISNA(VLOOKUP(A13,'Master List'!A:C,3,FALSE)), "Not Found", VLOOKUP(A13,'Master List'!A:C,3,FALSE))) -> edochong@yahoo.com | E13: HDMI > USB-C Adapter | F13: =IF(OR(A13="",E13="","",A13="?",E13="?"),"duplicate?",IF(COUNTIFS($A:A,A13,E:E,E13)>1,"yes","no")) -> no | G13: NA | H13: 45282 | K13: =IF(J13="","Date",IF(J13<>"",IF(K13="Date",NOW(),K13),"")) -> Date
A14: 912461828 | B14: 44810 | C14: =IF(ISBLANK(A14),"Name",IF(ISNA(VLOOKUP(A14,'Master List'!A:C,2,FALSE)), "Not Found", VLOOKUP(A14,'Master List'!A:C,2,FALSE))) -> Asharee Brown | D14: =IF(ISBLANK(A14), "Email",IF(ISNA(VLOOKUP(A14,'Master List'!A:C,3,FALSE)), "Not Found", VLOOKUP(A14,'Master List'!A:C,3,FALSE))) -> asbrown@sfsu.edu | E14: VGA > USB-C Adapter Adapter | F14: =IF(OR(A14="",E14="","",A14="?",E14="?"),"duplicate?",IF(COUNTIFS($A:A,A14,E:E,E14)>1,"yes","no")) -> no | H14: 45282 | K14: =IF(J14="","Date",IF(J14<>"",IF(K14="Date",NOW(),K14),"")) -> Date
A15: 912461828 | B15: 44810 | C15: =IF(ISBLANK(A15),"Name",IF(ISNA(VLOOKUP(A15,'Master List'!A:C,2,FALSE)), "Not Found", VLOOKUP(A15,'Master List'!A:C,2,FALSE))) -> Asharee Brown | D15: =IF(ISBLANK(A15), "Email",IF(ISNA(VLOOKUP(A15,'Master List'!A:C,3,FALSE)), "Not Found", VLOOKUP(A15,'Master List'!A:C,3,FALSE))) -> asbrown@sfsu.edu | E15: HDMI > USB-C Adapter | F15: =IF(OR(A15="",E15="","",A15="?",E15="?"),"duplicate?",IF(COUNTIFS($A:A,A15,E:E,E15)>1,"yes","no")) -> no | G15: NA | H15: 45282 | K15: =IF(J15="","Date",IF(J15<>"",IF(K15="Date",NOW(),K15),"")) -> Date
A16: 900045866 | B16: 44810 | C16: =IF(ISBLANK(A16),"Name",IF(ISNA(VLOOKUP(A16,'Master List'!A:C,2,FALSE)), "Not Found", VLOOKUP(A16,'Master List'!A:C,2,FALSE))) -> Elane Feng | D16: =IF(ISBLANK(A16), "Email",IF(ISNA(VLOOKUP(A16,'Master List'!A:C,3,FALSE)), "Not Found", VLOOKUP(A16,'Master List'!A:C,3,FALSE))) -> efeng@sfsu.edu | E16: Mac Power Adapter (USB-C) | F16: =IF(OR(A16="",E16="","",A16="?",E16="?"),"duplicate?",IF(COUNTIFS($A:A,A16,E:E,E16)>1,"yes","no")) -> no | G16: NA | H16: 45282 | K16: =IF(J16="","Date",IF(J16<>"",IF(K16="Date",NOW(),K16),"")) -> Date
A17: 906999384 | B17: 44810 | C17: =IF(ISBLANK(A17),"Name",IF(ISNA(VLOOKUP(A17,'Master List'!A:C,2,FALSE)), "Not Found", VLOOKUP(A17,'Master List'!A:C,2,FALSE))) -> Gail Baugh | D17: =IF(ISBLANK(A17), "Email",IF(ISNA(VLOOKUP(A17,'Master List'!A:C,3,FALSE)), "Not Found", VLOOKUP(A17,'Master List'!A:C,3,FALSE))) -> gailbaugh@sfsu.edu | E17: HDMI > USB-C Adapter | F17: =IF(OR(A17="",E17="","",A17="?",E17="?"),"duplicate?",IF(COUNTIFS($A:A,A17,E:E,E17)>1,"yes","no")) -> no | G17: NA | H17: 45282 | K17: =IF(J17="","Date",IF(J17<>"",IF(K17="Date",NOW(),K17),"")) -> Date
A18: 900015524 | B18: 44810 | C18: =IF(ISBLANK(A18),"Name",IF(ISNA(VLOOKUP(A18,'Master List'!A:C,2,FALSE)), "Not Found", VLOOKUP(A18,'Master List'!A:C,2,FALSE))) -> George Gassner | D18: =IF(ISBLANK(A18), "Email",IF(ISNA(VLOOKUP(A18,'Master List'!A:C,3,FALSE)), "Not Found", VLOOKUP(A18,'Master List'!A:C,3,FALSE))) -> gassner@sfsu.edu | E18: Webcam (Logi 720p) | F18: =IF(OR(A18="",E18="","",A18="?",E18="?"),"duplicate?",IF(COUNTIFS($A:A,A18,E:E,E18)>1,"yes","no")) -> no | H18: 45282 | K18: =IF(J18="","Date",IF(J18<>"",IF(K18="Date",NOW(),K18),"")) -> Date
A19: 908492564 | B19: 44810 | C19: =IF(ISBLANK(A19),"Name",IF(ISNA(VLOOKUP(A19,'Master List'!A:C,2,FALSE)), "Not Found", VLOOKUP(A19,'Master List'!A:C,2,FALSE))) -> Julietta Hua | D19: =IF(ISBLANK(A19), "Email",IF(ISNA(VLOOKUP(A19,'Master List'!A:C,3,FALSE)), "Not Found", VLOOKUP(A19,'Master List'!A:C,3,FALSE))) -> jyhua@sfsu.edu | E19: Multiport adapter (USB-C hub) (USB-C hub) | F19: =IF(OR(A19="",E19="","",A19="?",E19="?"),"duplicate?",IF(COUNTIFS($A:A,A19,E:E,E19)>1,"yes","no")) -> no | G19: NA | H19: 45282 | K19: =IF(J19="","Date",IF(J19<>"",IF(K19="Date",NOW(),K19),"")) -> Date
A20: 902476632 | B20: 44810 | C20: =IF(ISBLANK(A20),"Name",IF(ISNA(VLOOKUP(A20,'Master List'!A:C,2,FALSE)), "Not Found", VLOOKUP(A20,'Master List'!A:C,2,FALSE))) -> Matt Pico | D20: =IF(ISBLANK(A20), "Email",IF(ISNA(VLOOKUP(A20,'Master List'!A:C,3,FALSE)), "Not Found", VLOOKUP(A20,'Master List'!A:C,3,FALSE))) -> mpico@sfsu.edu | E20: HDMI > USB-C Adapter | F20: =IF(OR(A20="",E20="","",A20="?",E20="?"),"duplicate?",IF(COUNTIFS($A:A,A20,E:E,E20)>1,"yes","no")) -> no | G20: NA | H20: 45282 | K20: =IF(J20="","Date",IF(J20<>"",IF(K20="Date",NOW(),K20),"")) -> Date
A21: 918328884 | B21: 44810 | C21: =IF(ISBLANK(A21),"Name",IF(ISNA(VLOOKUP(A21,'Master List'!A:C,2,FALSE)), "Not Found", VLOOKUP(A21,'Master List'!A:C,2,FALSE))) -> Menaal Alowdi | D21: =IF(ISBLANK(A21), "Email",IF(ISNA(VLOOKUP(A21,'Master List'!A:C,3,FALSE)), "Not Found", VLOOKUP(A21,'Master List'!A:C,3,FALSE))) -> malowdi@mail.sfsu.edu | E21: HDMI > USB-C Adapter | F21: =IF(OR(A21="",E21="","",A21="?",E21="?"),"duplicate?",IF(COUNTIFS($A:A,A21,E:E,E21)>1,"yes","no")) -> no | G21: NA | H21: 45282 | K21: =IF(J21="","Date",IF(J21<>"",IF(K21="Date",NOW(),K21),"")) -> Date
A22: 909186933 | B22: 44810 | C22: =IF(ISBLANK(A22),"Name",IF(ISNA(VLOOKUP(A22,'Master List'!A:C,2,FALSE)), "Not Found", VLOOKUP(A22,'Master List'!A:C,2,FALSE))) -> Mahmood Monshipouri | D22: =IF(ISBLANK(A22), "Email",IF(ISNA(VLOOKUP(A22,'Master List'!A:C,3,FALSE)), "Not Found", VLOOKUP(A22,'Master List'!A:C,3,FALSE))) -> mmonship@sfsu.edu | E22: HDMI > USB-C Adapter | F22: =IF(OR(A22="",E22="","",A22="?",E22="?"),"duplicate?",IF(COUNTIFS($A:A,A22,E:E,E22)>1,"yes","no")) -> no | G22: NA | H22: 45282 | K22: =IF(J22="","Date",IF(J22<>"",IF(K22="Date",NOW(),K22),"")) -> Date
A23: 917253199 | B23: 44810 | C23: =IF(ISBLANK(A23),"Name",IF(ISNA(VLOOKUP(A23,'Master List'!A:C,2,FALSE)), "Not Found", VLOOKUP(A23,'Master List'!A:C,2,FALSE))) -> Robert Allen | D23: =IF(ISBLANK(A23), "Email",IF(ISNA(VLOOKUP(A23,'Master List'!A:C,3,FALSE)), "Not Found", VLOOKUP(A23,'Master List'!A:C,3,FALSE))) -> roballen@sfsu.edu | E23: HDMI > MDP Adapter | F23: =IF(OR(A23="",E23="","",A23="?",E23="?"),"duplicate?",IF(COUNTIFS($A:A,A23,E:E,E23)>1,"yes","no")) -> no | G23: NA | H23: 45282 | K23: =IF(J23="","Date",IF(J23<>"",IF(K23="Date",NOW(),K23),"")) -> Date
A24: 918848234 | B24: 44810 | C24: =IF(ISBLANK(A24),"Name",IF(ISNA(VLOOKUP(A24,'Master List'!A:C,2,FALSE)), "Not Found", VLOOKUP(A24,'Master List'!A:C,2,FALSE))) -> Sanchita Ghose | D24: =IF(ISBLANK(A24), "Email",IF(ISNA(VLOOKUP(A24,'Master List'!A:C,3,FALSE)), "Not Found", VLOOKUP(A24,'Master List'!A:C,3,FALSE))) -> sanchitaghose@sfsu.edu | E24: Keyboard+USB-C > USB-C Cable | F24: =IF(OR(A24="",E24="","",A24="?",E24="?"),"duplicate?",IF(COUNTIFS($A:A,A24,E:E,E24)>1,"yes","no")) -> no | G24: NA | H24: 45282 | K24: =IF(J24="","Date",IF(J24<>"",IF(K24="Date",NOW(),K24),"")) -> Date
A25: 915848432 | B25: 44810 | C25: =IF(ISBLANK(A25),"Name",IF(ISNA(VLOOKUP(A25,'Master List'!A:C,2,FALSE)), "Not Found", VLOOKUP(A25,'Master List'!A:C,2,FALSE))) -> Valerie Fernandez | D25: =IF(ISBLANK(A25), "Email",IF(ISNA(VLOOKUP(A25,'Master List'!A:C,3,FALSE)), "Not Found", VLOOKUP(A25,'Master List'!A:C,3,FALSE))) -> vfernandez3@sfsu.edu | E25: HDMI > USB-C Adapter | F25: =IF(OR(A25="",E25="","",A25="?",E25="?"),"duplicate?",IF(COUNTIFS($A:A,A25,E:E,E25)>1,"yes","no")) -> no | G25: NA | H25: 45282 | K25: =IF(J25="","Date",IF(J25<>"",IF(K25="Date",NOW(),K25),"")) -> Date
A26: 922404701 | B26: 44811 | C26: =IF(ISBLANK(A26),"Name",IF(ISNA(VLOOKUP(A26,'Master List'!A:C,2,FALSE)), "Not Found", VLOOKUP(A26,'Master List'!A:C,2,FALSE))) -> Anudeep Katukojwala | D26: =IF(ISBLANK(A26), "Email",IF(ISNA(VLOOKUP(A26,'Master List'!A:C,3,FALSE)), "Not Found", VLOOKUP(A26,'Master List'!A:C,3,FALSE))) -> akatukojwala@sfsu.edu | E26: Pen Tablet (Wacom Intuos) | F26: =IF(OR(A26="",E26="","",A26="?",E26="?"),"duplicate?",IF(COUNTIFS($A:A,A26,E:E,E26)>1,"yes","no")) -> no | H26: 45282 | K26: =IF(J26="","Date",IF(J26<>"",IF(K26="Date",NOW(),K26),"")) -> Date
A27: 922404701 | B27: 44811 | C27: =IF(ISBLANK(A27),"Name",IF(ISNA(VLOOKUP(A27,'Master List'!A:C,2,FALSE)), "Not Found", VLOOKUP(A27,'Master List'!A:C,2,FALSE))) -> Anudeep Katukojwala | D27: =IF(ISBLANK(A27), "Email",IF(ISNA(VLOOKUP(A27,'Master List'!A:C,3,FALSE)), "Not Found", VLOOKUP(A27,'Master List'!A:C,3,FALSE))) -> akatukojwala@sfsu.edu | E27: HDMI > USB-C Adapter | F27: =IF(OR(A27="",E27="","",A27="?",E27="?"),"duplicate?",IF(COUNTIFS($A:A,A27,E:E,E27)>1,"yes","no")) -> no | G27: NA | H27: 45282 | K27: =IF(J27="","Date",IF(J27<>"",IF(K27="Date",NOW(),K27),"")) -> Date
A28: 900204037 | B28: 44812 | C28: =IF(ISBLANK(A28),"Name",IF(ISNA(VLOOKUP(A28,'Master List'!A:C,2,FALSE)), "Not Found", VLOOKUP(A28,'Master List'!A:C,2,FALSE))) -> Carolyn Gencarella | D28: =IF(ISBLANK(A28), "Email",IF(ISNA(VLOOKUP(A28,'Master List'!A:C,3,FALSE)), "Not Found", VLOOKUP(A28,'Master List'!A:C,3,FALSE))) -> gencarellac@sfsu.edu | E28: VGA > USB-C Adapter Adapter | F28: =IF(OR(A28="",E28="","",A28="?",E28="?"),"duplicate?",IF(COUNTIFS($A:A,A28,E:E,E28)>1,"yes","no")) -> no | G28: NA | H28: 45282 | K28: =IF(J28="","Date",IF(J28<>"",IF(K28="Date",NOW(),K28),"")) -> Date
A29: 909819539 | B29: 44816 | C29: =IF(ISBLANK(A29),"Name",IF(ISNA(VLOOKUP(A29,'Master List'!A:C,2,FALSE)), "Not Found", VLOOKUP(A29,'Master List'!A:C,2,FALSE))) -> Nicholas Torres | D29: =IF(ISBLANK(A29), "Email",IF(ISNA(VLOOKUP(A29,'Master List'!A:C,3,FALSE)), "Not Found", VLOOKUP(A29,'Master List'!A:C,3,FALSE))) -> ntorres3@mail.sfsu.edu | E29: VGA > HDMI Adapter Adapter | F29: =IF(OR(A29="",E29="","",A29="?",E29="?"),"duplicate?",IF(COUNTIFS($A:A,A29,E:E,E29)>1,"yes","no")) -> no | G29: NA | H29: 45282 | K29: =IF(J29="","Date",IF(J29<>"",IF(K29="Date",NOW(),K29),"")) -> Date
A30: 907603858 | B30: 44817 | C30: =IF(ISBLANK(A30),"Name",IF(ISNA(VLOOKUP(A30,'Master List'!A:C,2,FALSE)), "Not Found", VLOOKUP(A30,'Master List'!A:C,2,FALSE))) -> Jason Harris-Boundy | D30: =IF(ISBLANK(A30), "Email",IF(ISNA(VLOOKUP(A30,'Master List'!A:C,3,FALSE)), "Not Found", VLOOKUP(A30,'Master List'!A:C,3,FALSE))) -> jchb@sfsu.edu | E30: HDMI > USB-C Adapter | F30: =IF(OR(A30="",E30="","",A30="?",E30="?"),"duplicate?",IF(COUNTIFS($A:A,A30,E:E,E30)>1,"yes","no")) -> no | G30: NA | H30: 45282 | K30: =IF(J30="","Date",IF(J30<>"",IF(K30="Date",NOW(),K30),"")) -> Date
A31: 909861620 | B31: 44817 | C31: =IF(ISBLANK(A31),"Name",IF(ISNA(VLOOKUP(A31,'Master List'!A:C,2,FALSE)), "Not Found", VLOOKUP(A31,'Master List'!A:C,2,FALSE))) -> Kwong-Liem Kwan | D31: =IF(ISBLANK(A31), "Email",IF(ISNA(VLOOKUP(A31,'Master List'!A:C,3,FALSE)), "Not Found", VLOOKUP(A31,'Master List'!A:C,3,FALSE))) -> kwan@sfsu.edu | E31: HDMI > USB-C Adapter | F31: =IF(OR(A31="",E31="","",A31="?",E31="?"),"duplicate?",IF(COUNTIFS($A:A,A31,E:E,E31)>1,"yes","no")) -> yes | H31: 45282 | K31: =IF(J31="","Date",IF(J31<>"",IF(K31="Date",NOW(),K31),"")) -> Date
A32: 918836274 | B32: 44818 | C32: =IF(ISBLANK(A32),"Name",IF(ISNA(VLOOKUP(A32,'Master List'!A:C,2,FALSE)), "Not Found", VLOOKUP(A32,'Master List'!A:C,2,FALSE))) -> Caroline Casper | D32: =IF(ISBLANK(A32), "Email",IF(ISNA(VLOOKUP(A32,'Master List'!A:C,3,FALSE)), "Not Found", VLOOKUP(A32,'Master List'!A:C,3,FALSE))) -> ccasper@sfsu.edu | E32: HDMI > USB-C Adapter | F32: =IF(OR(A32="",E32="","",A32="?",E32="?"),"duplicate?",IF(COUNTIFS($A:A,A32,E:E,E32)>1,"yes","no")) -> yes | G32: NA | H32: 45282 | K32: =IF(J32="","Date",IF(J32<>"",IF(K32="Date",NOW(),K32),"")) -> Date
A33: 911369841 | B33: 44818 | C33: =IF(ISBLANK(A33),"Name",IF(ISNA(VLOOKUP(A33,'Master List'!A:C,2,FALSE)), "Not Found", VLOOKUP(A33,'Master List'!A:C,2,FALSE))) -> Aiko Yoshino | D33: =IF(ISBLANK(A33), "Email",IF(ISNA(VLOOKUP(A33,'Master List'!A:C,3,FALSE)), "Not Found", VLOOKUP(A33,'Master List'!A:C,3,FALSE))) -> ayoshino@sfsu.edu | E33: HDMI > USB-C Adapter | F33: =IF(OR(A33="",E33="","",A33="?",E33="?"),"duplicate?",IF(COUNTIFS($A:A,A33,E:E,E33)>1,"yes","no")) -> yes | G33: NA | H33: 45282 | K33: =IF(J33="","Date",IF(J33<>"",IF(K33="Date",NOW(),K33),"")) -> Date
A34: 918834168 | B34: 44818 | C34: =IF(ISBLANK(A34),"Name",IF(ISNA(VLOOKUP(A34,'Master List'!A:C,2,FALSE)), "Not Found", VLOOKUP(A34,'Master List'!A:C,2,FALSE))) -> Jingyi Wang | D34: =IF(ISBLANK(A34), "Email",IF(ISNA(VLOOKUP(A34,'Master List'!A:C,3,FALSE)), "Not Found", VLOOKUP(A34,'Master List'!A:C,3,FALSE))) -> jingyiwang@sfsu.edu | E34: HDMI > USB-C Adapter | F34: =IF(OR(A34="",E34="","",A34="?",E34="?"),"duplicate?",IF(COUNTIFS($A:A,A34,E:E,E34)>1,"yes","no")) -> no | G34: NA | H34: 45282 | K34: =IF(J34="","Date",IF(J34<>"",IF(K34="Date",NOW(),K34),"")) -> Date
A35: 900029187 | B35: 44818 | C35: =IF(ISBLANK(A35),"Name",IF(ISNA(VLOOKUP(A35,'Master List'!A:C,2,FALSE)), "Not Found", VLOOKUP(A35,'Master List'!A:C,2,FALSE))) -> Karen Johnson-Brennan | D35: =IF(ISBLANK(A35), "Email",IF(ISNA(VLOOKUP(A35,'Master List'!A:C,3,FALSE)), "Not Found", VLOOKUP(A35,'Master List'!A:C,3,FALSE))) -> kcjb@sfsu.edu | E35: PA - Small | F35: =IF(OR(A35="",E35="","",A35="?",E35="?"),"duplicate?",IF(COUNTIFS($A:A,A35,E:E,E35)>1,"yes","no")) -> no | G35: NA | H35: 45282 | K35: =IF(J35="","Date",IF(J35<>"",IF(K35="Date",NOW(),K35),"")) -> Date
A36: 900025404 | B36: 44819 | C36: =IF(ISBLANK(A36),"Name",IF(ISNA(VLOOKUP(A36,'Master List'!A:C,2,FALSE)), "Not Found", VLOOKUP(A36,'Master List'!A:C,2,FALSE))) -> Bruce Heiman | D36: =IF(ISBLANK(A36), "Email",IF(ISNA(VLOOKUP(A36,'Master List'!A:C,3,FALSE)), "Not Found", VLOOKUP(A36,'Master List'!A:C,3,FALSE))) -> bheiman@sfsu.edu | E36: Multiport adapter (USB-C hub) (USB-C hub) | F36: =IF(OR(A36="",E36="","",A36="?",E36="?"),"duplicate?",IF(COUNTIFS($A:A,A36,E:E,E36)>1,"yes","no")) -> no | G36: N/A | H36: 45282 | K36: =IF(J36="","Date",IF(J36<>"",IF(K36="Date",NOW(),K36),"")) -> Date
A37: 906207684 | B37: 44819 | C37: =IF(ISBLANK(A37),"Name",IF(ISNA(VLOOKUP(A37,'Master List'!A:C,2,FALSE)), "Not Found", VLOOKUP(A37,'Master List'!A:C,2,FALSE))) -> Mark Shrayber | D37: =IF(ISBLANK(A37), "Email",IF(ISNA(VLOOKUP(A37,'Master List'!A:C,3,FALSE)), "Not Found", VLOOKUP(A37,'Master List'!A:C,3,FALSE))) -> mshraybe@sfsu.edu | E37: HDMI > USB-C Adapter | F37: =IF(OR(A37="",E37="","",A37="?",E37="?"),"duplicate?",IF(COUNTIFS($A:A,A37,E:E,E37)>1,"yes","no")) -> no | G37: NA | H37: 45282 | K37: =IF(J37="","Date",IF(J37<>"",IF(K37="Date",NOW(),K37),"")) -> Date
A38: 922404701 | B38: 44823 | C38: =IF(ISBLANK(A38),"Name",IF(ISNA(VLOOKUP(A38,'Master List'!A:C,2,FALSE)), "Not Found", VLOOKUP(A38,'Master List'!A:C,2,FALSE))) -> Anudeep Katukojwala | D38: =IF(ISBLANK(A38), "Email",IF(ISNA(VLOOKUP(A38,'Master List'!A:C,3,FALSE)), "Not Found", VLOOKUP(A38,'Master List'!A:C,3,FALSE))) -> akatukojwala@sfsu.edu | E38: USB-A > USB-C Adapter Adapter | F38: =IF(OR(A38="",E38="","",A38="?",E38="?"),"duplicate?",IF(COUNTIFS($A:A,A38,E:E,E38)>1,"yes","no")) -> no | G38: NA | H38: 45282 | K38: =IF(J38="","Date",IF(J38<>"",IF(K38="Date",NOW(),K38),"")) -> Date
A39: 900018007 | B39: 44823 | C39: =IF(ISBLANK(A39),"Name",IF(ISNA(VLOOKUP(A39,'Master List'!A:C,2,FALSE)), "Not Found", VLOOKUP(A39,'Master List'!A:C,2,FALSE))) -> Deborah Miller | D39: =IF(ISBLANK(A39), "Email",IF(ISNA(VLOOKUP(A39,'Master List'!A:C,3,FALSE)), "Not Found", VLOOKUP(A39,'Master List'!A:C,3,FALSE))) -> debbiem@sfsu.edu | E39: HDMI > MDP Adapter | F39: =IF(OR(A39="",E39="","",A39="?",E39="?"),"duplicate?",IF(COUNTIFS($A:A,A39,E:E,E39)>1,"yes","no")) -> no | G39: N/A | H39: 45282 | K39: =IF(J39="","Date",IF(J39<>"",IF(K39="Date",NOW(),K39),"")) -> Date
A40: 917242331 | B40: 44823 | C40: =IF(ISBLANK(A40),"Name",IF(ISNA(VLOOKUP(A40,'Master List'!A:C,2,FALSE)), "Not Found", VLOOKUP(A40,'Master List'!A:C,2,FALSE))) -> Ilana Crispi | D40: =IF(ISBLANK(A40), "Email",IF(ISNA(VLOOKUP(A40,'Master List'!A:C,3,FALSE)), "Not Found", VLOOKUP(A40,'Master List'!A:C,3,FALSE))) -> icrispi@sfsu.edu | E40: Headset (Logi H390) | F40: =IF(OR(A40="",E40="","",A40="?",E40="?"),"duplicate?",IF(COUNTIFS($A:A,A40,E:E,E40)>1,"yes","no")) -> no | G40: N/A | H40: 45282 | K40: =IF(J40="","Date",IF(J40<>"",IF(K40="Date",NOW(),K40),"")) -> Date
...

Sheet Student GoPros
A1: ID | B1: Date | C1: Name | D1: Email | E1: Equipment Description | F1: Duplicate | G1: GoPro # | H1: Expected Return Date | I1: Checked out by | J1: Checked in by | K1: Returned Date | L1: Notes
A2: 916490346 | B2: =IF(A2="","Date",IF(A2<>"",IF(B2="Date",NOW(),B2),"")) -> 45329.683 | C2: Vessela Anguelova | D2: vanguelova@sfsu.edu | E2: GoPro 4 w/ tripod | F2: =IF(OR(A2="",E2="","",A2="?",E2="?"),"duplicate?",IF(COUNTIFS($A:A,A2,E:E,E2)>1,"yes","no")) -> no | G2: GP74 | H2: 45384 | I2: Kevin | J2: Mari | K2: =IF(J2="","Date",IF(J2<>"",IF(K2="Date",NOW(),K2),"")) -> 45372.657
A3: 923240510 | B3: =IF(A3="","Date",IF(A3<>"",IF(B3="Date",NOW(),B3),"")) -> 45336.637 | C3: =IF(ISBLANK(A3),"Name",IF(ISNA(VLOOKUP(A3,'Master List'!A:C,2,FALSE)), "Not Found", VLOOKUP(A3,'Master List'!A:C,2,FALSE))) -> Kunie Kikunaga | D3: =IF(ISBLANK(A3), "Email",IF(ISNA(VLOOKUP(A3,'Master List'!A:C,3,FALSE)), "Not Found", VLOOKUP(A3,'Master List'!A:C,3,FALSE))) -> kkikunaga@sfsu.edu | E3: GoPro 11 w/ tripod | F3: =IF(OR(A3="",E3="","",A3="?",E3="?"),"duplicate?",IF(COUNTIFS($A:A,A3,E:E,E3)>1,"yes","no")) -> yes | G3: GP 77 | H3: 45356 | I3: Sam | J3: Jeremy | K3: =IF(J3="","Date",IF(J3<>"",IF(K3="Date",NOW(),K3),"")) -> 45363.774 | L3: GoPro 11
A4: 920938353 | B4: =IF(A4="","Date",IF(A4<>"",IF(B4="Date",NOW(),B4),"")) -> 45337.56 | C4: =IF(ISBLANK(A4),"Name",IF(ISNA(VLOOKUP(A4,'Master List'!A:C,2,FALSE)), "Not Found", VLOOKUP(A4,'Master List'!A:C,2,FALSE))) -> Maelynn Le | D4: =IF(ISBLANK(A4), "Email",IF(ISNA(VLOOKUP(A4,'Master List'!A:C,3,FALSE)), "Not Found", VLOOKUP(A4,'Master List'!A:C,3,FALSE))) -> mle12@mail.sfsu.edu | E4: GoPro 11 w/ tripod | F4: =IF(OR(A4="",E4="","",A4="?",E4="?"),"duplicate?",IF(COUNTIFS($A:A,A4,E:E,E4)>1,"yes","no")) -> no | G4: GP120 | H4: 45379 | I4: Sam | J4: Sam | K4: =IF(J4="","Date",IF(J4<>"",IF(K4="Date",NOW(),K4),"")) -> 45378.688 | L4: Already returned the clear water cases (not sure why) -Kevin
A5: 923240510 | B5: =IF(A5="","Date",IF(A5<>"",IF(B5="Date",NOW(),B5),"")) -> 45341.501 | C5: =IF(ISBLANK(A5),"Name",IF(ISNA(VLOOKUP(A5,'Master List'!A:C,2,FALSE)), "Not Found", VLOOKUP(A5,'Master List'!A:C,2,FALSE))) -> Kunie Kikunaga | D5: =IF(ISBLANK(A5), "Email",IF(ISNA(VLOOKUP(A5,'Master List'!A:C,3,FALSE)), "Not Found", VLOOKUP(A5,'Master List'!A:C,3,FALSE))) -> kkikunaga@sfsu.edu | E5: GoPro Wireless Mic | F5: =IF(OR(A5="",E5="","",A5="?",E5="?"),"duplicate?",IF(COUNTIFS($A:A,A5,E:E,E5)>1,"yes","no")) -> yes | G5: ? | H5: 45356 | I5: Ariana | J5: Jeremy | K5: =IF(J5="","Date",IF(J5<>"",IF(K5="Date",NOW(),K5),"")) -> 45363.774
A6: 911104394 | B6: =IF(A6="","Date",IF(A6<>"",IF(B6="Date",NOW(),B6),"")) -> 45343.672 | C6: =IF(ISBLANK(A6),"Name",IF(ISNA(VLOOKUP(A6,'Master List'!A:C,2,FALSE)), "Not Found", VLOOKUP(A6,'Master List'!A:C,2,FALSE))) -> Natalie Ayala | D6: =IF(ISBLANK(A6), "Email",IF(ISNA(VLOOKUP(A6,'Master List'!A:C,3,FALSE)), "Not Found", VLOOKUP(A6,'Master List'!A:C,3,FALSE))) -> nayala@sfsu.edu | E6: GoPro 11 w/ tripod | F6: =IF(OR(A6="",E6="","",A6="?",E6="?"),"duplicate?",IF(COUNTIFS($A:A,A6,E:E,E6)>1,"yes","no")) -> no | G6: GP111 | H6: 46818 | I6: Kevin | J6: Sam | K6: =IF(J6="","Date",IF(J6<>"",IF(K6="Date",NOW(),K6),"")) -> 45357.607 | L6: USB C-C cable was not included, apprently was not included when loaned out.
A7: 923660943 | B7: =IF(A7="","Date",IF(A7<>"",IF(B7="Date",NOW(),B7),"")) -> 45350.367 | C7: =IF(ISBLANK(A7),"Name",IF(ISNA(VLOOKUP(A7,'Master List'!A:C,2,FALSE)), "Not Found", VLOOKUP(A7,'Master List'!A:C,2,FALSE))) -> Shufen Ma | D7: =IF(ISBLANK(A7), "Email",IF(ISNA(VLOOKUP(A7,'Master List'!A:C,3,FALSE)), "Not Found", VLOOKUP(A7,'Master List'!A:C,3,FALSE))) -> sma@sfsu.edu | E7: GoPro 11 w/ tripod | F7: =IF(OR(A7="",E7="","",A7="?",E7="?"),"duplicate?",IF(COUNTIFS($A:A,A7,E:E,E7)>1,"yes","no")) -> no | G7: GP118 | H7: 45357 | I7: Josh | J7: Kevin | K7: =IF(J7="","Date",IF(J7<>"",IF(K7="Date",NOW(),K7),"")) -> 45422.653
A8: 923660943 | B8: =IF(A8="","Date",IF(A8<>"",IF(B8="Date",NOW(),B8),"")) -> 45350.367 | C8: =IF(ISBLANK(A8),"Name",IF(ISNA(VLOOKUP(A8,'Master List'!A:C,2,FALSE)), "Not Found", VLOOKUP(A8,'Master List'!A:C,2,FALSE))) -> Shufen Ma | D8: =IF(ISBLANK(A8), "Email",IF(ISNA(VLOOKUP(A8,'Master List'!A:C,3,FALSE)), "Not Found", VLOOKUP(A8,'Master List'!A:C,3,FALSE))) -> sma@sfsu.edu | E8: GoPro Wireless Mic | F8: =IF(OR(A8="",E8="","",A8="?",E8="?"),"duplicate?",IF(COUNTIFS($A:A,A8,E:E,E8)>1,"yes","no")) -> no | H8: 45357 | I8: Josh | J8: Kevin | K8: =IF(J8="","Date",IF(J8<>"",IF(K8="Date",NOW(),K8),"")) -> 45422.653
A9: 920743353 | B9: =IF(A9="","Date",IF(A9<>"",IF(B9="Date",NOW(),B9),"")) -> 45350.368 | C9: =IF(ISBLANK(A9),"Name",IF(ISNA(VLOOKUP(A9,'Master List'!A:C,2,FALSE)), "Not Found", VLOOKUP(A9,'Master List'!A:C,2,FALSE))) -> Eli Dinkelspiel | D9: =IF(ISBLANK(A9), "Email",IF(ISNA(VLOOKUP(A9,'Master List'!A:C,3,FALSE)), "Not Found", VLOOKUP(A9,'Master List'!A:C,3,FALSE))) -> edinkelspiel@sfsu.edu | E9: GoPro (Hero 8) | F9: =IF(OR(A9="",E9="","",A9="?",E9="?"),"duplicate?",IF(COUNTIFS($A:A,A9,E:E,E9)>1,"yes","no")) -> no | G9: GP82 / GP14? | H9: 45357 | I9: Josh | J9: Cloud | K9: =IF(#REF!="","Date",IF(#REF!<>"",IF(K9="Date",NOW(),K9),"")) -> #REF!
A10: 920743353 | B10: =IF(A10="","Date",IF(A10<>"",IF(B10="Date",NOW(),B10),"")) -> 45350.369 | C10: =IF(ISBLANK(A10),"Name",IF(ISNA(VLOOKUP(A10,'Master List'!A:C,2,FALSE)), "Not Found", VLOOKUP(A10,'Master List'!A:C,2,FALSE))) -> Eli Dinkelspiel | D10: =IF(ISBLANK(A10), "Email",IF(ISNA(VLOOKUP(A10,'Master List'!A:C,3,FALSE)), "Not Found", VLOOKUP(A10,'Master List'!A:C,3,FALSE))) -> edinkelspiel@sfsu.edu | E10: GoPro Wireless Mic | F10: =IF(OR(A10="",E10="","",A10="?",E10="?"),"duplicate?",IF(COUNTIFS($A:A,A10,E:E,E10)>1,"yes","no")) -> no | G10: WM3 | H10: 45357 | I10: Josh | J10: Cloud | K10: =IF(J9="","Date",IF(J9<>"",IF(K10="Date",NOW(),K10),"")) -> 45429.67
A11: 913060374 | B11: =IF(A11="","Date",IF(A11<>"",IF(B11="Date",NOW(),B11),"")) -> 45350.37 | C11: =IF(ISBLANK(A11),"Name",IF(ISNA(VLOOKUP(A11,'Master List'!A:C,2,FALSE)), "Not Found", VLOOKUP(A11,'Master List'!A:C,2,FALSE))) -> Paul Medeiros | D11: =IF(ISBLANK(A11), "Email",IF(ISNA(VLOOKUP(A11,'Master List'!A:C,3,FALSE)), "Not Found", VLOOKUP(A11,'Master List'!A:C,3,FALSE))) -> pauljmed@mail.sfsu.edu | E11: GoPro (Hero 8) | F11: =IF(OR(A11="",E11="","",A11="?",E11="?"),"duplicate?",IF(COUNTIFS($A:A,A11,E:E,E11)>1,"yes","no")) -> no | G11: GP85 and Tripod | H11: 45357 | I11: Mari | J11: Mari | K11: =IF(J11="","Date",IF(J11<>"",IF(K11="Date",NOW(),K11),"")) -> 45358.696 | L11: Cristian snapped off the small flap
A12: 913060374 | B12: =IF(A12="","Date",IF(A12<>"",IF(B12="Date",NOW(),B12),"")) -> 45350.371 | C12: =IF(ISBLANK(A12),"Name",IF(ISNA(VLOOKUP(A12,'Master List'!A:C,2,FALSE)), "Not Found", VLOOKUP(A12,'Master List'!A:C,2,FALSE))) -> Paul Medeiros | D12: =IF(ISBLANK(A12), "Email",IF(ISNA(VLOOKUP(A12,'Master List'!A:C,3,FALSE)), "Not Found", VLOOKUP(A12,'Master List'!A:C,3,FALSE))) -> pauljmed@mail.sfsu.edu | E12: GoPro Wireless Mic | F12: =IF(OR(A12="",E12="","",A12="?",E12="?"),"duplicate?",IF(COUNTIFS($A:A,A12,E:E,E12)>1,"yes","no")) -> no | H12: 45357 | I12: Mari | J12: Mari | K12: =IF(J12="","Date",IF(J12<>"",IF(K12="Date",NOW(),K12),"")) -> 45358.696
A13: 900016746 | B13: =IF(A13="","Date",IF(A13<>"",IF(B13="Date",NOW(),B13),"")) -> 45350.704 | C13: =IF(ISBLANK(A13),"Name",IF(ISNA(VLOOKUP(A13,'Master List'!A:C,2,FALSE)), "Not Found", VLOOKUP(A13,'Master List'!A:C,2,FALSE))) -> Kurt Nutting | D13: =IF(ISBLANK(A13), "Email",IF(ISNA(VLOOKUP(A13,'Master List'!A:C,3,FALSE)), "Not Found", VLOOKUP(A13,'Master List'!A:C,3,FALSE))) -> knutting@sfsu.edu | E13: External DVD Drive | F13: =IF(OR(A13="",E13="","",A13="?",E13="?"),"duplicate?",IF(COUNTIFS($A:A,A13,E:E,E13)>1,"yes","no")) -> no | H13: In two weeks | I13: Mari | K13: =IF(J13="","Date",IF(J13<>"",IF(K13="Date",NOW(),K13),"")) -> Date
A14: 923658993 | B14: =IF(A14="","Date",IF(A14<>"",IF(B14="Date",NOW(),B14),"")) -> 45351.798 | C14: =IF(ISBLANK(A14),"Name",IF(ISNA(VLOOKUP(A14,'Master List'!A:C,2,FALSE)), "Not Found", VLOOKUP(A14,'Master List'!A:C,2,FALSE))) -> Colin Schildhauer | D14: =IF(ISBLANK(A14), "Email",IF(ISNA(VLOOKUP(A14,'Master List'!A:C,3,FALSE)), "Not Found", VLOOKUP(A14,'Master List'!A:C,3,FALSE))) -> SchildhauerC@sfsu.edu | E14: GoPro 11 w/ tripod | F14: =IF(OR(A14="",E14="","",A14="?",E14="?"),"duplicate?",IF(COUNTIFS($A:A,A14,E:E,E14)>1,"yes","no")) -> no | G14: GP-90 and Tripod GP-100 | H14: 45365 | I14: Adisat | J14: Cloud | K14: =IF(J14="","Date",IF(J14<>"",IF(K14="Date",NOW(),K14),"")) -> 45421.686
A15: 911104394 | B15: =IF(A15="","Date",IF(A15<>"",IF(B15="Date",NOW(),B15),"")) -> 45357.602 | C15: =IF(ISBLANK(A15),"Name",IF(ISNA(VLOOKUP(A15,'Master List'!A:C,2,FALSE)), "Not Found", VLOOKUP(A15,'Master List'!A:C,2,FALSE))) -> Natalie Ayala | D15: =IF(ISBLANK(A15), "Email",IF(ISNA(VLOOKUP(A15,'Master List'!A:C,3,FALSE)), "Not Found", VLOOKUP(A15,'Master List'!A:C,3,FALSE))) -> nayala@sfsu.edu | E15: GoPro 4 w/ tripod | F15: =IF(OR(A15="",E15="","",A15="?",E15="?"),"duplicate?",IF(COUNTIFS($A:A,A15,E:E,E15)>1,"yes","no")) -> yes | G15: GP 53 | H15: 45371 | I15: Sam | J15: Mari | K15: =IF(J15="","Date",IF(J15<>"",IF(K15="Date",NOW(),K15),"")) -> 45371.666 | L15: Tripod from previous rental (same student)
A16: 923661671 | B16: =IF(A16="","Date",IF(A16<>"",IF(B16="Date",NOW(),B16),"")) -> 45362.616 | C16: Zachary Crowley | D16: zcrowley@sfsu.edu | E16: GoPro 11 w/ tripod | F16: =IF(OR(A16="",E16="","",A16="?",E16="?"),"duplicate?",IF(COUNTIFS($A:A,A16,E:E,E16)>1,"yes","no")) -> no | G16: GP-83 | H16: 45377 | I16: ARIANA | J16: Sam | K16: =IF(J16="","Date",IF(J16<>"",IF(K16="Date",NOW(),K16),"")) -> 45379.643
A17: 923240510 | B17: =IF(A17="","Date",IF(A17<>"",IF(B17="Date",NOW(),B17),"")) -> 45363.774 | C17: =IF(ISBLANK(A17),"Name",IF(ISNA(VLOOKUP(A17,'Master List'!A:C,2,FALSE)), "Not Found", VLOOKUP(A17,'Master List'!A:C,2,FALSE))) -> Kunie Kikunaga | D17: =IF(ISBLANK(A17), "Email",IF(ISNA(VLOOKUP(A17,'Master List'!A:C,3,FALSE)), "Not Found", VLOOKUP(A17,'Master List'!A:C,3,FALSE))) -> kkikunaga@sfsu.edu | E17: GoPro 11 w/ tripod | F17: =IF(OR(A17="",E17="","",A17="?",E17="?"),"duplicate?",IF(COUNTIFS($A:A,A17,E:E,E17)>1,"yes","no")) -> yes | G17: GP 77 | H17: 45377 | I17: Jeremy | J17: Mari | K17: =IF(J17="","Date",IF(J17<>"",IF(K17="Date",NOW(),K17),"")) -> 45378.531
A18: 923240510 | B18: =IF(A18="","Date",IF(A18<>"",IF(B18="Date",NOW(),B18),"")) -> 45363.774 | C18: =IF(ISBLANK(A18),"Name",IF(ISNA(VLOOKUP(A18,'Master List'!A:C,2,FALSE)), "Not Found", VLOOKUP(A18,'Master List'!A:C,2,FALSE))) -> Kunie Kikunaga | D18: =IF(ISBLANK(A18), "Email",IF(ISNA(VLOOKUP(A18,'Master List'!A:C,3,FALSE)), "Not Found", VLOOKUP(A18,'Master List'!A:C,3,FALSE))) -> kkikunaga@sfsu.edu | E18: GoPro Wireless Mic | F18: =IF(OR(A18="",E18="","",A18="?",E18="?"),"duplicate?",IF(COUNTIFS($A:A,A18,E:E,E18)>1,"yes","no")) -> yes | H18: 45377 | I18: Jeremy | J18: Mari | K18: =IF(J18="","Date",IF(J18<>"",IF(K18="Date",NOW(),K18),"")) -> 45378.531
A19: 911104394 | B19: =IF(A19="","Date",IF(A19<>"",IF(B19="Date",NOW(),B19),"")) -> 45371.666 | C19: =IF(ISBLANK(A19),"Name",IF(ISNA(VLOOKUP(A19,'Master List'!A:C,2,FALSE)), "Not Found", VLOOKUP(A19,'Master List'!A:C,2,FALSE))) -> Natalie Ayala | D19: =IF(ISBLANK(A19), "Email",IF(ISNA(VLOOKUP(A19,'Master List'!A:C,3,FALSE)), "Not Found", VLOOKUP(A19,'Master List'!A:C,3,FALSE))) -> nayala@sfsu.edu | E19: GoPro 4 w/ tripod | F19: =IF(OR(A19="",E19="","",A19="?",E19="?"),"duplicate?",IF(COUNTIFS($A:A,A19,E:E,E19)>1,"yes","no")) -> yes | G19: GP 53 | H19: 45385 | I19: Mari | J19: Cloud | K19: =IF(J19="","Date",IF(J19<>"",IF(K19="Date",NOW(),K19),"")) -> 45406.684
A20: 923864653 | B20: =IF(A20="","Date",IF(A20<>"",IF(B20="Date",NOW(),B20),"")) -> 45385.639 | C20: =IF(ISBLANK(A20),"Name",IF(ISNA(VLOOKUP(A20,'Master List'!A:C,2,FALSE)), "Not Found", VLOOKUP(A20,'Master List'!A:C,2,FALSE))) -> Nesma Elhizzawi | D20: =IF(ISBLANK(A20), "Email",IF(ISNA(VLOOKUP(A20,'Master List'!A:C,3,FALSE)), "Not Found", VLOOKUP(A20,'Master List'!A:C,3,FALSE))) -> nelhizzawi@sfsu.edu | E20: GoPro 11 w/ tripod | F20: =IF(OR(A20="",E20="","",A20="?",E20="?"),"duplicate?",IF(COUNTIFS($A:A,A20,E:E,E20)>1,"yes","no")) -> yes | G20: GP 115 | H20: 45399 | I20: Sam | J20: Cloud | K20: =IF(J20="","Date",IF(J20<>"",IF(K20="Date",NOW(),K20),"")) -> 45397.932
A21: 923864653 | B21: =IF(A21="","Date",IF(A21<>"",IF(B21="Date",NOW(),B21),"")) -> 45397.952 | C21: =IF(ISBLANK(A21),"Name",IF(ISNA(VLOOKUP(A21,'Master List'!A:C,2,FALSE)), "Not Found", VLOOKUP(A21,'Master List'!A:C,2,FALSE))) -> Nesma Elhizzawi | D21: =IF(ISBLANK(A21), "Email",IF(ISNA(VLOOKUP(A21,'Master List'!A:C,3,FALSE)), "Not Found", VLOOKUP(A21,'Master List'!A:C,3,FALSE))) -> nelhizzawi@sfsu.edu | E21: GoPro 11 w/ tripod | F21: =IF(OR(A21="",E21="","",A21="?",E21="?"),"duplicate?",IF(COUNTIFS($A:A,A21,E:E,E21)>1,"yes","no")) -> yes | G21: GP 115 | H21: 45411 | I21: Cloud | J21: Cloud | K21: =IF(J21="","Date",IF(J21<>"",IF(K21="Date",NOW(),K21),"")) -> 45411.636
A22: 911104394 | B22: =IF(A22="","Date",IF(A22<>"",IF(B22="Date",NOW(),B22),"")) -> 45406.684 | C22: =IF(ISBLANK(A22),"Name",IF(ISNA(VLOOKUP(A22,'Master List'!A:C,2,FALSE)), "Not Found", VLOOKUP(A22,'Master List'!A:C,2,FALSE))) -> Natalie Ayala | D22: =IF(ISBLANK(A22), "Email",IF(ISNA(VLOOKUP(A22,'Master List'!A:C,3,FALSE)), "Not Found", VLOOKUP(A22,'Master List'!A:C,3,FALSE))) -> nayala@sfsu.edu | E22: GoPro 4 w/ tripod | F22: =IF(OR(A22="",E22="","",A22="?",E22="?"),"duplicate?",IF(COUNTIFS($A:A,A22,E:E,E22)>1,"yes","no")) -> yes | G22: GP 53 | H22: 45427 | I22: Cloud | J22: Josh | K22: =IF(J22="","Date",IF(J22<>"",IF(K22="Date",NOW(),K22),"")) -> 45426.703
A23: 918785600 | B23: =IF(A23="","Date",IF(A23<>"",IF(B23="Date",NOW(),B23),"")) -> 45560.526 | C23: Keren Nichole Zendejas | D23: kzendejas@sfsu.edu | E23: GoPro 11 w/ tripod | F23: =IF(OR(A23="",E23="","",A23="?",E23="?"),"duplicate?",IF(COUNTIFS($A:A,A23,E:E,E23)>1,"yes","no")) -> yes | G23: GP 82 | H23: 45567 | I23: Kanisha | J23: Cloud | K23: =IF(J23="","Date",IF(J23<>"",IF(K23="Date",NOW(),K23),"")) -> 45567.527
A24: 923901885 | B24: =IF(A24="","Date",IF(A24<>"",IF(B24="Date",NOW(),B24),"")) -> 45567.676 | C24: =IF(ISBLANK(A24),"Name",IF(ISNA(VLOOKUP(A24,'Master List'!A:C,2,FALSE)), "Not Found", VLOOKUP(A24,'Master List'!A:C,2,FALSE))) -> Yasi Martin-Partovi | D24: =IF(ISBLANK(A24), "Email",IF(ISNA(VLOOKUP(A24,'Master List'!A:C,3,FALSE)), "Not Found", VLOOKUP(A24,'Master List'!A:C,3,FALSE))) -> jmartinpartovi@sfsu.edu | E24: GoPro 11 w/ tripod | F24: =IF(OR(A24="",E24="","",A24="?",E24="?"),"duplicate?",IF(COUNTIFS($A:A,A24,E:E,E24)>1,"yes","no")) -> yes | G24: GP 90 | H24: 45574 | I24: Cloud | J24: Sam | K24: =IF(J24="","Date",IF(J24<>"",IF(K24="Date",NOW(),K24),"")) -> 45568.674
A25: 921051297 | B25: =IF(A25="","Date",IF(A25<>"",IF(B25="Date",NOW(),B25),"")) -> 45575.599 | C25: =IF(ISBLANK(A25),"Name",IF(ISNA(VLOOKUP(A25,'Master List'!A:C,2,FALSE)), "Not Found", VLOOKUP(A25,'Master List'!A:C,2,FALSE))) -> Samuel Reid | D25: =IF(ISBLANK(A25), "Email",IF(ISNA(VLOOKUP(A25,'Master List'!A:C,3,FALSE)), "Not Found", VLOOKUP(A25,'Master List'!A:C,3,FALSE))) -> sreid1@mail.sfsu.edu | E25: GoPro 11 w/ tripod | F25: =IF(OR(A25="",E25="","",A25="?",E25="?"),"duplicate?",IF(COUNTIFS($A:A,A25,E:E,E25)>1,"yes","no")) -> yes | G25: He also check out a microphone | H25: 45589 | I25: Ariana | J25: Sam | K25: =IF(J25="","Date",IF(J25<>"",IF(K25="Date",NOW(),K25),"")) -> 45579.53
A26: 920457548 | B26: =IF(A26="","Date",IF(A26<>"",IF(B26="Date",NOW(),B26),"")) -> 45576.411 | C26: Maria Del Castillo Schmidhiber | D26: mdelcastilloschmidhiber@mail.sfsu.edu | E26: GoPro 11 w/ tripod | F26: =IF(OR(A26="",E26="","",A26="?",E26="?"),"duplicate?",IF(COUNTIFS($A:A,A26,E:E,E26)>1,"yes","no")) -> no | G26: GP 118 | H26: 45583 | I26: Adisat | J26: Cloud | K26: =IF(J26="","Date",IF(J26<>"",IF(K26="Date",NOW(),K26),"")) -> 45581.656
A27: 921051297 | B27: =IF(A27="","Date",IF(A27<>"",IF(B27="Date",NOW(),B27),"")) -> 45588.596 | C27: =IF(ISBLANK(A27),"Name",IF(ISNA(VLOOKUP(A27,'Master List'!A:C,2,FALSE)), "Not Found", VLOOKUP(A27,'Master List'!A:C,2,FALSE))) -> Samuel Reid | D27: =IF(ISBLANK(A27), "Email",IF(ISNA(VLOOKUP(A27,'Master List'!A:C,3,FALSE)), "Not Found", VLOOKUP(A27,'Master List'!A:C,3,FALSE))) -> sreid1@mail.sfsu.edu | E27: GoPro 11 w/ tripod | F27: =IF(OR(A27="",E27="","",A27="?",E27="?"),"duplicate?",IF(COUNTIFS($A:A,A27,E:E,E27)>1,"yes","no")) -> yes | G27: GP 88 | H27: 45610 | I27: Kanisha | J27: Mari | K27: =IF(J27="","Date",IF(J27<>"",IF(K27="Date",NOW(),K27),"")) -> 45614.634 | L27: He checked out a microphone too and Tripod 14
A28: 917694887 | B28: =IF(A28="","Date",IF(A28<>"",IF(B28="Date",NOW(),B28),"")) -> 45590.626 | C28: =IF(ISBLANK(A28),"Name",IF(ISNA(VLOOKUP(A28,'Master List'!A:C,2,FALSE)), "Not Found", VLOOKUP(A28,'Master List'!A:C,2,FALSE))) -> Joey Samuel Ng | D28: jng9@sfsu.edu | E28: GoPro 11 w/ tripod | F28: =IF(OR(A28="",E28="","",A28="?",E28="?"),"duplicate?",IF(COUNTIFS($A:A,A28,E:E,E28)>1,"yes","no")) -> no | H28: End of Semester | I28: Athan | J28: Ethan | K28: =IF(J28="","Date",IF(J28<>"",IF(K28="Date",NOW(),K28),"")) -> 45595.668
A29: 923901846 | B29: =IF(A29="","Date",IF(A29<>"",IF(B29="Date",NOW(),B29),"")) -> 45596.688 | C29: =IF(ISBLANK(A29),"Name",IF(ISNA(VLOOKUP(A29,'Master List'!A:C,2,FALSE)), "Not Found", VLOOKUP(A29,'Master List'!A:C,2,FALSE))) -> Sofia Fulgoni | D29: =IF(ISBLANK(A29), "Email",IF(ISNA(VLOOKUP(A29,'Master List'!A:C,3,FALSE)), "Not Found", VLOOKUP(A29,'Master List'!A:C,3,FALSE))) -> sfulgoni@sfsu.edu | E29: GoPro 11 w/ tripod | F29: =IF(OR(A29="",E29="","",A29="?",E29="?"),"duplicate?",IF(COUNTIFS($A:A,A29,E:E,E29)>1,"yes","no")) -> yes | G29: GP 95 | H29: 45610 | I29: Sam | J29: Mari | K29: =IF(J29="","Date",IF(J29<>"",IF(K29="Date",NOW(),K29),"")) -> 45602.698
A30: 922788305 | B30: =IF(A30="","Date",IF(A30<>"",IF(B30="Date",NOW(),B30),"")) -> 45601.678 | C30: =IF(ISBLANK(A30),"Name",IF(ISNA(VLOOKUP(A30,'Master List'!A:C,2,FALSE)), "Not Found", VLOOKUP(A30,'Master List'!A:C,2,FALSE))) -> Anesu Mupombwa | D30: =IF(ISBLANK(A30), "Email",IF(ISNA(VLOOKUP(A30,'Master List'!A:C,3,FALSE)), "Not Found", VLOOKUP(A30,'Master List'!A:C,3,FALSE))) -> amupombwa@sfsu.edu | E30: GoPro 11 w/ tripod | F30: =IF(OR(A30="",E30="","",A30="?",E30="?"),"duplicate?",IF(COUNTIFS($A:A,A30,E:E,E30)>1,"yes","no")) -> no | H30: End of Semester | I30: Athan | K30: =IF(J30="","Date",IF(J30<>"",IF(K30="Date",NOW(),K30),"")) -> Date
A31: 918785600 | B31: =IF(A31="","Date",IF(A31<>"",IF(B31="Date",NOW(),B31),"")) -> 45604.351 | C31: Keren Nichole Zendejas | D31: kzendejas@sfsu.edu | E31: GoPro 11 w/ tripod | F31: =IF(OR(A31="",E31="","",A31="?",E31="?"),"duplicate?",IF(COUNTIFS($A:A,A31,E:E,E31)>1,"yes","no")) -> yes | G31: GP 118 | H31: 45615 | J31: Cloud | K31: =IF(J31="","Date",IF(J31<>"",IF(K31="Date",NOW(),K31),"")) -> 45616.535
A32: 924309136 | B32: =IF(A32="","Date",IF(A32<>"",IF(B32="Date",NOW(),B32),"")) -> 45615.693 | C32: =IF(ISBLANK(A32),"Name",IF(ISNA(VLOOKUP(A32,'Master List'!A:C,2,FALSE)), "Not Found", VLOOKUP(A32,'Master List'!A:C,2,FALSE))) -> Lewis Haidt | D32: =IF(ISBLANK(A32), "Email",IF(ISNA(VLOOKUP(A32,'Master List'!A:C,3,FALSE)), "Not Found", VLOOKUP(A32,'Master List'!A:C,3,FALSE))) -> lhaidt@sfsu.edu | E32: GoPro 11 w/ tripod | F32: =IF(OR(A32="",E32="","",A32="?",E32="?"),"duplicate?",IF(COUNTIFS($A:A,A32,E:E,E32)>1,"yes","no")) -> yes | G32: GP 88 | H32: 45629 | I32: Athan | J32: Sam | K32: =IF(J32="","Date",IF(J32<>"",IF(K32="Date",NOW(),K32),"")) -> 45638.67
A33: 921782430 | B33: =IF(A33="","Date",IF(A33<>"",IF(B33="Date",NOW(),B33),"")) -> 45631.521 | C33: =IF(ISBLANK(A33),"Name",IF(ISNA(VLOOKUP(A33,'Master List'!A:C,2,FALSE)), "Not Found", VLOOKUP(A33,'Master List'!A:C,2,FALSE))) -> Raymond Hernandez | D33: =IF(ISBLANK(A33), "Email",IF(ISNA(VLOOKUP(A33,'Master List'!A:C,3,FALSE)), "Not Found", VLOOKUP(A33,'Master List'!A:C,3,FALSE))) -> rhernandez15@sfsu.edu | E33: GoPro 11 w/ tripod | F33: =IF(OR(A33="",E33="","",A33="?",E33="?"),"duplicate?",IF(COUNTIFS($A:A,A33,E:E,E33)>1,"yes","no")) -> no | G33: GP 114 | H33: Early Jan | I33: Sam | J33: Athan | K33: =IF(J33="","Date",IF(J33<>"",IF(K33="Date",NOW(),K33),"")) -> 45772.372
A34: 924307290 | B34: =IF(A34="","Date",IF(A34<>"",IF(B34="Date",NOW(),B34),"")) -> 45692.758 | C34: =IF(ISBLANK(A34),"Name",IF(ISNA(VLOOKUP(A34,'Master List'!A:C,2,FALSE)), "Not Found", VLOOKUP(A34,'Master List'!A:C,2,FALSE))) -> Tyler Berkson | D34: =IF(ISBLANK(A34), "Email",IF(ISNA(VLOOKUP(A34,'Master List'!A:C,3,FALSE)), "Not Found", VLOOKUP(A34,'Master List'!A:C,3,FALSE))) -> tberkson@sfsu.edu | E34: GoPro 11 w/ tripod | F34: =IF(OR(A34="",E34="","",A34="?",E34="?"),"duplicate?",IF(COUNTIFS($A:A,A34,E:E,E34)>1,"yes","no")) -> no | G34: GP88 | H34: 45706 | I34: Mari | J34: Yukti | K34: =IF(J34="","Date",IF(J34<>"",IF(K34="Date",NOW(),K34),"")) -> 45727.79 | L34: Turning it in a week later
A35: 923901885 | B35: =IF(A35="","Date",IF(A35<>"",IF(B35="Date",NOW(),B35),"")) -> 45699.798 | C35: =IF(ISBLANK(A35),"Name",IF(ISNA(VLOOKUP(A35,'Master List'!A:C,2,FALSE)), "Not Found", VLOOKUP(A35,'Master List'!A:C,2,FALSE))) -> Yasi Martin-Partovi | D35: =IF(ISBLANK(A35), "Email",IF(ISNA(VLOOKUP(A35,'Master List'!A:C,3,FALSE)), "Not Found", VLOOKUP(A35,'Master List'!A:C,3,FALSE))) -> jmartinpartovi@sfsu.edu | E35: GoPro 11 w/ tripod | F35: =IF(OR(A35="",E35="","",A35="?",E35="?"),"duplicate?",IF(COUNTIFS($A:A,A35,E:E,E35)>1,"yes","no")) -> yes | G35: GP98 | H35: 45712 | I35: Yukti | J35: Mari | K35: =IF(J35="","Date",IF(J35<>"",IF(K35="Date",NOW(),K35),"")) -> 45783.697
A36: 921051297 | B36: =IF(A36="","Date",IF(A36<>"",IF(B36="Date",NOW(),B36),"")) -> 45701.64 | C36: =IF(ISBLANK(A36),"Name",IF(ISNA(VLOOKUP(A36,'Master List'!A:C,2,FALSE)), "Not Found", VLOOKUP(A36,'Master List'!A:C,2,FALSE))) -> Samuel Reid | D36: =IF(ISBLANK(A36), "Email",IF(ISNA(VLOOKUP(A36,'Master List'!A:C,3,FALSE)), "Not Found", VLOOKUP(A36,'Master List'!A:C,3,FALSE))) -> sreid1@mail.sfsu.edu | E36: GoPro 11 w/ tripod | F36: =IF(OR(A36="",E36="","",A36="?",E36="?"),"duplicate?",IF(COUNTIFS($A:A,A36,E:E,E36)>1,"yes","no")) -> yes | G36: GP84 | H36: 45722 | I36: Yukti | J36: Athan | K36: =IF(J36="","Date",IF(J36<>"",IF(K36="Date",NOW(),K36),"")) -> 45765.042 | L36: Returned + mic, tripod April 18 - returned tripod
A37: 916125371 | B37: =IF(A37="","Date",IF(A37<>"",IF(B37="Date",NOW(),B37),"")) -> 45705.641 | C37: =IF(ISBLANK(A37),"Name",IF(ISNA(VLOOKUP(A37,'Master List'!A:C,2,FALSE)), "Not Found", VLOOKUP(A37,'Master List'!A:C,2,FALSE))) -> Mayra Torres | D37: =IF(ISBLANK(A37), "Email",IF(ISNA(VLOOKUP(A37,'Master List'!A:C,3,FALSE)), "Not Found", VLOOKUP(A37,'Master List'!A:C,3,FALSE))) -> mtorres5@sfsu.edu | E37: GoPro 11 w/ tripod | F37: =IF(OR(A37="",E37="","",A37="?",E37="?"),"duplicate?",IF(COUNTIFS($A:A,A37,E:E,E37)>1,"yes","no")) -> yes | G37: GP118 | H37: 45713 | I37: Cloud | J37: Cloud | K37: =IF(J37="","Date",IF(J37<>"",IF(K37="Date",NOW(),K37),"")) -> 45723.69 | L37: Tripod GP-14
A38: 922838524 | B38: =IF(A38="","Date",IF(A38<>"",IF(B38="Date",NOW(),B38),"")) -> 45706.686 | C38: =IF(ISBLANK(A38),"Name",IF(ISNA(VLOOKUP(A38,'Master List'!A:C,2,FALSE)), "Not Found", VLOOKUP(A38,'Master List'!A:C,2,FALSE))) -> Nicholas Knight | D38: =IF(ISBLANK(A38), "Email",IF(ISNA(VLOOKUP(A38,'Master List'!A:C,3,FALSE)), "Not Found", VLOOKUP(A38,'Master List'!A:C,3,FALSE))) -> nknight2@sfsu.edu | E38: GoPro 11 w/ tripod | F38: =IF(OR(A38="",E38="","",A38="?",E38="?"),"duplicate?",IF(COUNTIFS($A:A,A38,E:E,E38)>1,"yes","no")) -> no | G38: GP117 | H38: March 4th | I38: Mari | J38: Mari | K38: =IF(J38="","Date",IF(J38<>"",IF(K38="Date",NOW(),K38),"")) -> 45748.682 | L38: Didnt borrow Tripod
A39: 921219673 | B39: =IF(A39="","Date",IF(A39<>"",IF(B39="Date",NOW(),B39),"")) -> 45708.789 | C39: =IF(ISBLANK(A39),"Name",IF(ISNA(VLOOKUP(A39,'Master List'!A:C,2,FALSE)), "Not Found", VLOOKUP(A39,'Master List'!A:C,2,FALSE))) -> Erik Malagon-Leon | D39: =IF(ISBLANK(A39), "Email",IF(ISNA(VLOOKUP(A39,'Master List'!A:C,3,FALSE)), "Not Found", VLOOKUP(A39,'Master List'!A:C,3,FALSE))) -> emalagonleon@sfsu.edu | E39: GoPro 11 w/ tripod | F39: =IF(OR(A39="",E39="","",A39="?",E39="?"),"duplicate?",IF(COUNTIFS($A:A,A39,E:E,E39)>1,"yes","no")) -> no | G39: GP89 | H39: March 6th | I39: Yukti | J39: Yukti | K39: =IF(J39="","Date",IF(J39<>"",IF(K39="Date",NOW(),K39),"")) -> 45722.628 | L39: TRIPOD- GP-100
A40: 921345149 | B40: =IF(A40="","Date",IF(A40<>"",IF(B40="Date",NOW(),B40),"")) -> 45709.392 | C40: =IF(ISBLANK(A40),"Name",IF(ISNA(VLOOKUP(A40,'Master List'!A:C,2,FALSE)), "Not Found", VLOOKUP(A40,'Master List'!A:C,2,FALSE))) -> Ryan Pearce | D40: rpearce@sfsu.edu | E40: GoPro 11 w/ tripod | F40: =IF(OR(A40="",E40="","",A40="?",E40="?"),"duplicate?",IF(COUNTIFS($A:A,A40,E:E,E40)>1,"yes","no")) -> no | G40: GP93 | H40: 45716 | I40: Jason | K40: =IF(J40="","Date",IF(J40<>"",IF(K40="Date",NOW(),K40),"")) -> Date
...

Sheet Master List
A1: 922374775 | B1: Joey Cuomo | C1: jcuomoscanzi@sfsu.edu
A2: 900000197 | B2: Mark Roberge | C2: roberge@sfsu.edu
A3: 900000249 | B3: Tom Holton | C3: tholton@sfsu.edu
A4: 900000340 | B4: Erik Peper | C4: epeper@sfsu.edu
A5: 900000431 | B5: Bruce Manning | C5: bmanning@sfsu.edu
A6: 900000483 | B6: Susan Zieff | C6: susangz@sfsu.edu
A7: 900000574 | B7: Jono Kornfeld | C7: jonok@sfsu.edu
A8: 900000808 | B8: Kenneth Monteiro | C8: monteiro@sfsu.edu
A9: 900000821 | B9: Masahiko Minami | C9: mminami@sfsu.edu
A10: 900000951 | B10: Ricardo Gomes | C10: ricgomes@sfsu.edu
A11: 900001003 | B11: Michael Goldman | C11: goldman@sfsu.edu
A12: 900001042 | B12: Jamie Eng | C12: jeng@sfsu.edu
... A2737: 923022942 | B2737: Alexis Hooper | C2737: ahooper2@sfsu.edu
A2738: 908492005 | B2738: Kazunori Okada | C2738: kazokada@sfsu.edu
A2739: 918850808 | B2739: Ried Wagner | C2739: riedwagner@sfsu.edu
A2740: 909072104 | B2740: Noah Price | C2740: nprice@sfsu.edu
A2741: 917158819 | B2741: Carolina De Robertis | C2741: caro@sfsu.edu
A2742: 922215018 | B2742: Lan De Vera | C2742: ldevera@sfsu.edu
A2743: 922386176 | B2743: Stanislav Shaposhnikov | C2743: sshaposhnikov@sfsu.edu
A2744: 918837691 | B2744: Michelle Montoya | C2744: mmontoy@sfsu.edu
A2745: 916804478 | B2745: Victor Aguilar | C2745: vaguila4@sfsu.edu
A2746: 916181362 | B2746: Ty Maniulit | C2746: tymaniulit@sfsu.edu
A2747: 900030006 | B2747: Christopher Clark | C2747: cclark@sfsu.edu
A2748: 918850145 | B2748: Zia Davidian | C2748: zdavidian@sfsu.edu
A2749: 900028329 | B2749: Sheldon Gen | C2749: sgen@sfsu.edu
A2750: 917461355 | B2750: Alcides Fuentes | C2750: alcidesfuentes@sfsu.edu
... A2754: 904421185 | B2754: John Ryan | C2754: jbr@sfsu.edu
A2755: Jason Bell | B2755: Jason Bell | C2755: jbell@asi.sfsu.edu
A2756: 921790152 | B2756: Julio Torress | C2756: jtorres30@sfsu.edu
A2757: Elizabeth Hallford | B2757: Elizabeth Hallford | C2757: betsey8050@me.com
A2758: 918851679 | B2758: Rebecca Cheng | C2758: rebeccacheng@sfsu.edu
A2759: 900020828 | B2759: Amy Sueyoshi | C2759: sueyoshi@sfsu.edu
A2760: 918844633 | B2760: Evan Jaynes | C2760: jaynes@sfsu.edu
A2761: 921279525 | B2761: Luis Poncio | C2761: lponcio@mail.sfsu.edu
A2762: 918838822 | B2762: Matthew Menor | C2762: menor@sfsu.edu
A2763: 918099577 | B2763: Time Ubungen | C2763: time@sfsu.edu
A2764: 920197873 | B2764: J.C. Gonzales | C2764: jj.gonzales@me.com
A2765: 904975115 | B2765: Elizabeth Hallford | C2765: betsey8050@mac.com
A2766: 900040562 | B2766: Sally G Pasion | C2766: pasion@sfsu.edu
A2767: 915553046 | B2767: Alexandra Theodotou | C2767: atheodotou@sfsu.edu
...

Sheet Returned_checkout
A1: SFSU ID number | B1: Date | C1: Name | D1: Email | E1: Equipment Description | G1: Equipment ID (if applicable) | H1: Expected Return Date | I1: Checked out by | J1: Checked in by | K1: Returned Date | L1: Notes | M1: DEBT COLLECTOR
A2: 909168824 | B2: 44854 | C2: Ian Sinapuelas | D2: =IF(ISBLANK(B2), "Email",IF(ISNA(VLOOKUP(A2,'Master List'!A:C,3,FALSE)), "Not Found", VLOOKUP(A2,'Master List'!A:C,3,FALSE))) -> sinapuel@sfsu.edu | E2: Ethernet > USB-C Adapter | H2: 3 Weeks | K2: 37563 | M2: =IF(AND(COUNTIF(#REF!, Returned_checkout!A53)=0, ISBLANK(K2)),"Yes", "No") -> #REF!
A3: 920775489 | B3: 44895 | C3: Katelyn Endow | D3: =IF(ISBLANK(B3), "Email",IF(ISNA(VLOOKUP(A3,'Master List'!A:C,3,FALSE)), "Not Found", VLOOKUP(A3,'Master List'!A:C,3,FALSE))) -> kendow@sfsu.edu | E3: Camcorder (Sony 4K) | H3: end of semester | I3: Ritu | J3: Kevin | K3: 44578 | M3: =IF(AND(COUNTIF(#REF!, Returned_checkout!A68)=0, ISBLANK(K3)),"Yes", "No") -> #REF!
A4: 913869494 | B4: 44902 | C4: Nikolas Nackley | D4: =IF(ISBLANK(B4), "Email",IF(ISNA(VLOOKUP(A4,'Master List'!A:C,3,FALSE)), "Not Found", VLOOKUP(A4,'Master List'!A:C,3,FALSE))) -> nnackley@sfsu.edu | E4: Camcorder (Sony 4K) | H4: 44907 | I4: Larissa | J4: Kevin | K4: 44578 | M4: =IF(AND(COUNTIF(#REF!, Returned_checkout!A102)=0, ISBLANK(K4)),"Yes", "No") -> #REF!
A5: 901610000 | B5: 44834 | C5: Benjamin Sabey | D5: =IF(ISBLANK(B5), "Email",IF(ISNA(VLOOKUP(A5,'Master List'!A:C,3,FALSE)), "Not Found", VLOOKUP(A5,'Master List'!A:C,3,FALSE))) -> sabey@sfsu.edu | E5: Projector - Loose (CP-EX250N) | G5: LCD450 | H5: a week | J5: Rithik | K5: 44593 | L5: email sent 1/20/23 | M5: =IF(AND(COUNTIF(#REF!, Returned_checkout!A17)=0, ISBLANK(K5)),"Yes", "No") -> #REF!
A6: 918839459 | B6: 44823 | C6: Alexandra Hinck | D6: =IF(ISBLANK(B6), "Email",IF(ISNA(VLOOKUP(A6,'Master List'!A:C,3,FALSE)), "Not Found", VLOOKUP(A6,'Master List'!A:C,3,FALSE))) -> ahinck@sfsu.edu | E6: HDMI > USB-C Adapter | G6: N/A | H6: one day | K6: 44823 | M6: =IF(AND(COUNTIF(#REF!, Returned_checkout!A3)=0, ISBLANK(K6)),"Yes", "No") -> #REF!
A7: 900005774 | B7: 44823 | C7: M Schoerke | D7: =IF(ISBLANK(B7), "Email",IF(ISNA(VLOOKUP(A7,'Master List'!A:C,3,FALSE)), "Not Found", VLOOKUP(A7,'Master List'!A:C,3,FALSE))) -> schoerke@sfsu.edu | E7: HDMI > USB-C Adapter | G7: N/A | H7: one day | K7: 44823 | M7: =IF(AND(COUNTIF(#REF!, Returned_checkout!A89)=0, ISBLANK(K7)),"Yes", "No") -> #REF!
A8: 902221312 | B8: 44823 | C8: Paul Glanting | D8: =IF(ISBLANK(B8), "Email",IF(ISNA(VLOOKUP(A8,'Master List'!A:C,3,FALSE)), "Not Found", VLOOKUP(A8,'Master List'!A:C,3,FALSE))) -> pbg@mail.sfsu.edu | E8: HDMI > USB-C Adapter | G8: N/A | H8: one day | K8: 44823 | M8: =IF(AND(COUNTIF(#REF!, Returned_checkout!A103)=0, ISBLANK(K8)),"Yes", "No") -> #REF!
A9: 908543108 | B9: 44825 | C9: Kevin D Croshal | D9: =IF(ISBLANK(B9), "Email",IF(ISNA(VLOOKUP(A9,'Master List'!A:C,3,FALSE)), "Not Found", VLOOKUP(A9,'Master List'!A:C,3,FALSE))) -> kcroshal@sfsu.edu | E9: Blu-ray/DVD Player | H9: Later tonight | K9: 44825 | M9: =IF(AND(COUNTIF(#REF!, Returned_checkout!A75)=0, ISBLANK(K9)),"Yes", "No") -> #REF!
A10: 907441085 | B10: 44826 | C10: Cathy Rath | D10: =IF(ISBLANK(B10), "Email",IF(ISNA(VLOOKUP(A10,'Master List'!A:C,3,FALSE)), "Not Found", VLOOKUP(A10,'Master List'!A:C,3,FALSE))) -> crath@sfsu.edu | E10: Tripod - Small | G10: Webcam-6 AT Lib 85 | H10: one day | K10: 44826 | M10: =IF(AND(COUNTIF(#REF!, Returned_checkout!A22)=0, ISBLANK(K10)),"Yes", "No") -> #REF!
A11: 907441085 | B11: 44826 | C11: Cathy Rath | D11: =IF(ISBLANK(B11), "Email",IF(ISNA(VLOOKUP(A11,'Master List'!A:C,3,FALSE)), "Not Found", VLOOKUP(A11,'Master List'!A:C,3,FALSE))) -> crath@sfsu.edu | E11: Webcam (Logi C920s) | G11: ES-CTP-001 | H11: one day | K11: 44826 | M11: =IF(AND(COUNTIF(#REF!, Returned_checkout!A23)=0, ISBLANK(K11)),"Yes", "No") -> #REF!
A12: 907441085 | B12: 44826 | C12: Cathy Rath | D12: =IF(ISBLANK(B12), "Email",IF(ISNA(VLOOKUP(A12,'Master List'!A:C,3,FALSE)), "Not Found", VLOOKUP(A12,'Master List'!A:C,3,FALSE))) -> crath@sfsu.edu | E12: HDMI > USB-C Adapter | H12: one day | K12: 44826 | M12: =IF(AND(COUNTIF(#REF!, Returned_checkout!A24)=0, ISBLANK(K12)),"Yes", "No") -> #REF!
A13: 918844984 | B13: 44830 | C13: Meredith Stefran | D13: =IF(ISBLANK(B13), "Email",IF(ISNA(VLOOKUP(A13,'Master List'!A:C,3,FALSE)), "Not Found", VLOOKUP(A13,'Master List'!A:C,3,FALSE))) -> msafran@sfsu.edu | E13: HDMI > MDP Adapter | H13: A Week | K13: 44830 | M13: =IF(AND(COUNTIF(#REF!, Returned_checkout!A96)=0, ISBLANK(K13)),"Yes", "No") -> #REF!
A14: 913032515 | B14: 44830 | C14: Marisa Gymson | D14: =IF(ISBLANK(B14), "Email",IF(ISNA(VLOOKUP(A14,'Master List'!A:C,3,FALSE)), "Not Found", VLOOKUP(A14,'Master List'!A:C,3,FALSE))) -> mjimison@sfsu.edu | E14: HDMI > MDP Adapter | H14: a day | K14: 44831 | M14: =IF(AND(COUNTIF(#REF!, Returned_checkout!A93)=0, ISBLANK(K14)),"Yes", "No") -> #REF!
A15: 912817092 | B15: 44832 | C15: Deepika Ahuja | D15: =IF(ISBLANK(B15), "Email",IF(ISNA(VLOOKUP(A15,'Master List'!A:C,3,FALSE)), "Not Found", VLOOKUP(A15,'Master List'!A:C,3,FALSE))) -> deepikaahuja@sfsu.edu | E15: Headset (Logi H390) | H15: ? | K15: 44832 | M15: =IF(AND(COUNTIF(#REF!, Returned_checkout!A39)=0, ISBLANK(K15)),"Yes", "No") -> #REF!
A16: 904119858 | B16: 44833 | C16: Arturo Arritta | D16: =IF(ISBLANK(B16), "Email",IF(ISNA(VLOOKUP(A16,'Master List'!A:C,3,FALSE)), "Not Found", VLOOKUP(A16,'Master List'!A:C,3,FALSE))) -> aarrieta@sfsu.edu | E16: DVD The War: 1. A Necessarly War | H16: ? | K16: 44833 | M16: =IF(AND(COUNTIF(#REF!, Returned_checkout!A10)=0, ISBLANK(K16)),"Yes", "No") -> #REF!
A17: 904119858 | B17: 44833 | C17: Arturo Arritta | D17: =IF(ISBLANK(B17), "Email",IF(ISNA(VLOOKUP(A17,'Master List'!A:C,3,FALSE)), "Not Found", VLOOKUP(A17,'Master List'!A:C,3,FALSE))) -> aarrieta@sfsu.edu | E17: DVD 500 nations Cauldron of War | G17: 68401 | H17: Picked up last semester | K17: 44833 | M17: =IF(AND(COUNTIF(#REF!, Returned_checkout!A11)=0, ISBLANK(K17)),"Yes", "No") -> #REF!
A18: 904119858 | B18: 44833 | C18: Arturo Arritta | D18: =IF(ISBLANK(B18), "Email",IF(ISNA(VLOOKUP(A18,'Master List'!A:C,3,FALSE)), "Not Found", VLOOKUP(A18,'Master List'!A:C,3,FALSE))) -> aarrieta@sfsu.edu | E18: Blu-ray/DVD Player | G18: 89875 | H18: a week | K18: 44833 | M18: =IF(AND(COUNTIF(#REF!, Returned_checkout!A12)=0, ISBLANK(K18)),"Yes", "No") -> #REF!
A19: 916483521 | B19: 44833 | C19: Tomomi Kinukawa | D19: =IF(ISBLANK(B19), "Email",IF(ISNA(VLOOKUP(A19,'Master List'!A:C,3,FALSE)), "Not Found", VLOOKUP(A19,'Master List'!A:C,3,FALSE))) -> tkinukaw@sfsu.edu | E19: HDMI > MDP Adapter | H19: Returned from last semester | K19: 44833 | M19: =IF(AND(COUNTIF(#REF!, Returned_checkout!A123)=0, ISBLANK(K19)),"Yes", "No") -> #REF!
A20: 900030903 | B20: 44830 | C20: Ping Hsiao | D20: =IF(ISBLANK(B20), "Email",IF(ISNA(VLOOKUP(A20,'Master List'!A:C,3,FALSE)), "Not Found", VLOOKUP(A20,'Master List'!A:C,3,FALSE))) -> phsiao@sfsu.edu | E20: HDMI > USB-C Adapter | H20: 2 Weeks | K20: 44834 | M20: =IF(AND(COUNTIF(#REF!, Returned_checkout!A104)=0, ISBLANK(K20)),"Yes", "No") -> #REF!
A21: 911216610 | B21: 44826 | C21: Kim Nguyen | D21: =IF(ISBLANK(B21), "Email",IF(ISNA(VLOOKUP(A21,'Master List'!A:C,3,FALSE)), "Not Found", VLOOKUP(A21,'Master List'!A:C,3,FALSE))) -> kimn@sfsu.edu | E21: PA - Small | H21: A Week | K21: 44837 | M21: =IF(AND(COUNTIF(#REF!, Returned_checkout!A76)=0, ISBLANK(K21)),"Yes", "No") -> #REF!
A22: 912975029 | B22: 44837 | C22: Andrea Swei | D22: =IF(ISBLANK(B22), "Email",IF(ISNA(VLOOKUP(A22,'Master List'!A:C,3,FALSE)), "Not Found", VLOOKUP(A22,'Master List'!A:C,3,FALSE))) -> aswei@sfsu.edu | E22: VGA > USB-C Adapter Adapter | H22: end of the day | K22: 44837 | M22: =IF(AND(COUNTIF(#REF!, Returned_checkout!A7)=0, ISBLANK(K22)),"Yes", "No") -> #REF!
A23: 912333934 | B23: 44837 | C23: CAROLINA MARTINEZ | D23: =IF(ISBLANK(B23), "Email",IF(ISNA(VLOOKUP(A23,'Master List'!A:C,3,FALSE)), "Not Found", VLOOKUP(A23,'Master List'!A:C,3,FALSE))) -> cmartine@sfsu.edu | E23: HDMI > USB-C Adapter | H23: A DAY | K23: 44837 | M23: =IF(AND(COUNTIF(#REF!, Returned_checkout!A21)=0, ISBLANK(K23)),"Yes", "No") -> #REF!
A24: 902976066 | B24: 44838 | C24: Fenicia Jacks | D24: =IF(ISBLANK(B24), "Email",IF(ISNA(VLOOKUP(A24,'Master List'!A:C,3,FALSE)), "Not Found", VLOOKUP(A24,'Master List'!A:C,3,FALSE))) -> jacksf@sfsu.edu | E24: HDMI > MDP Adapter | J24: Dylan | K24: 44838 | M24: =IF(AND(COUNTIF(#REF!, Returned_checkout!A50)=0, ISBLANK(K24)),"Yes", "No") -> #REF!
A25: 900011585 | B25: 44838 | C25: Venise Wangner | D25: =IF(ISBLANK(B25), "Email",IF(ISNA(VLOOKUP(A25,'Master List'!A:C,3,FALSE)), "Not Found", VLOOKUP(A25,'Master List'!A:C,3,FALSE))) -> vwagner@sfsu.edu | E25: VHS Cart | G25: 81076 @HSS154 | H25: Today | J25: Kevin | K25: 44838 | M25: =IF(AND(COUNTIF(#REF!, Returned_checkout!A134)=0, ISBLANK(K25)),"Yes", "No") -> #REF!
A26: 918831256 | B26: 44839 | C26: Michelle Toney | D26: =IF(ISBLANK(B26), "Email",IF(ISNA(VLOOKUP(A26,'Master List'!A:C,3,FALSE)), "Not Found", VLOOKUP(A26,'Master List'!A:C,3,FALSE))) -> mstoney@sfsu.edu | E26: VGA > HDMI Adapter Adapter | G26: VGAHD-4 | H26: end of semester | K26: 44839 | M26: =IF(AND(COUNTIF(#REF!, Returned_checkout!A97)=0, ISBLANK(K26)),"Yes", "No") -> #REF!
A27: 912222407 | B27: 44838 | C27: Sean Crouch | D27: =IF(ISBLANK(B27), "Email",IF(ISNA(VLOOKUP(A27,'Master List'!A:C,3,FALSE)), "Not Found", VLOOKUP(A27,'Master List'!A:C,3,FALSE))) -> scrouch3@sfsu.edu | E27: HDMI > MDP Adapter | H27: end of semester | K27: 44845 | M27: =IF(AND(COUNTIF(#REF!, Returned_checkout!A114)=0, ISBLANK(K27)),"Yes", "No") -> #REF!
